Workbook

Sheet Raw Data
A1: File Name | B1: Pay Cycle | C1: Pay Sequence | D1: Employer | E1: Employer Address | F1: Employee Name | G1: Employee Address | H1: Account | I1: Net Pay | J1: Employee ID | K1: Work Period Start | L1: Work Period End | M1: Employee Title | N1: Pay Date | O1: EARNINGS - Description 1 | P1: EARNINGS - Hrs 1 | Q1: EARNINGS - Rate 1 | R1: EARNINGS - Amount 1 | S1: EARNINGS - Cumul. 1 | T1: EARNINGS - Description 2 | U1: EARNINGS - Hrs 2 | V1: EARNINGS - Rate 2 | W1: EARNINGS - Amount 2 | X1: EARNINGS - Cumul. 2 | Y1: EARNINGS - Description 3 | Z1: EARNINGS - Hrs 3 | AA1: EARNINGS - Rate 3 | AB1: EARNINGS - Amount 3 | AC1: EARNINGS - Cumul. 3 | AD1: EARNINGS - Description 4 | AE1: EARNINGS - Hrs 4 | AF1: EARNINGS - Rate 4 | AG1: EARNINGS - Amount 4 | AH1: EARNINGS - Cumul. 4 | AI1: EARNINGS - Description 5 | AJ1: EARNINGS - Hrs 5 | AK1: EARNINGS - Rate 5 | AL1: EARNINGS - Amount 5 | AM1: EARNINGS - Cumul. 5 | AN1: EARNINGS - Description 6 | AO1: EARNINGS - Hrs 6 | AP1: EARNINGS - Rate 6 | AQ1: EARNINGS - Amount 6 | AR1: EARNINGS - Cumul. 6 | AS1: EARNINGS - Description 7 | AT1: EARNINGS - Hrs 7 | AU1: EARNINGS - Rate 7 | AV1: EARNINGS - Amount 7 | AW1: EARNINGS - Cumul. 7 | AX1: EARNINGS - Description 8 | AY1: EARNINGS - Hrs 8 | AZ1: EARNINGS - Rate 8 | BA1: EARNINGS - Amount 8 | BB1: EARNINGS - Cumul. 8 | BC1: EARNINGS - Description 9 | BD1: EARNINGS - Hrs 9 | BE1: EARNINGS - Rate 9 | BF1: EARNINGS - Amount 9 | BG1: EARNINGS - Cumul. 9 | BH1: EARNINGS - Description 10 | BI1: EARNINGS - Hrs 10 | BJ1: EARNINGS - Rate 10 | BK1: EARNINGS - Amount 10 | BL1: EARNINGS - Cumul. 10 | BM1: DEDUCTIONS - Description 1 | BN1: DEDUCTIONS - Amount 1 | BO1: DEDUCTIONS - Cumul. 1 | BP1: DEDUCTIONS - Description 2 | BQ1: DEDUCTIONS - Amount 2 | BR1: DEDUCTIONS - Cumul. 2 | BS1: DEDUCTIONS - Description 3 | BT1: DEDUCTIONS - Amount 3 | BU1: DEDUCTIONS - Cumul. 3 | BV1: DEDUCTIONS - Description 4 | BW1: DEDUCTIONS - Amount 4 | BX1: DEDUCTIONS - Cumul. 4 | BY1: DEDUCTIONS - Description 5 | BZ1: DEDUCTIONS - Amount 5 | CA1: DEDUCTIONS - Cumul. 5 | CB1: DEDUCTIONS - Description 6 | CC1: DEDUCTIONS - Amount 6 | CD1: DEDUCTIONS - Cumul. 6 | CE1: DEDUCTIONS - Description 7 | CF1: DEDUCTIONS - Amount 7 | CG1: DEDUCTIONS - Cumul. 7 | CH1: DEDUCTIONS - Description 8 | CI1: DEDUCTIONS - Amount 8 | CJ1: DEDUCTIONS - Cumul. 8 | CK1: DEDUCTIONS - Description 9 | CL1: DEDUCTIONS - Amount 9 | CM1: DEDUCTIONS - Cumul. 9 | CN1: DEDUCTIONS - Description 10 | CO1: DEDUCTIONS - Amount 10 | CP1: DEDUCTIONS - Cumul. 10 | CQ1: ACCRUALS - Description 1 | CR1: ACCRUALS - Amount 1 | CS1: ACCRUALS - Cumul. 1 | CT1: ACCRUALS - Description 2 | CU1: ACCRUALS - Amount 2 | CV1: ACCRUALS - Cumul. 2 | CW1: ACCRUALS - Description 3 | CX1: ACCRUALS - Amount 3 | CY1: ACCRUALS - Cumul. 3 | CZ1: ACCRUALS - Description 4 | DA1: ACCRUALS - Amount 4 | DB1: ACCRUALS - Cumul. 4 | DC1: ACCRUALS - Description 5 | DD1: ACCRUALS - Amount 5 | DE1: ACCRUALS - Cumul. 5 | DF1: ACCRUALS - Description 6 | DG1: ACCRUALS - Amount 6 | DH1: ACCRUALS - Cumul. 6 | DI1: ACCRUALS - Description 7 | DJ1: ACCRUALS - Amount 7 | DK1: ACCRUALS - Cumul. 7 | DL1: ACCRUALS - Description 8 | DM1: ACCRUALS - Amount 8 | DN1: ACCRUALS - Cumul. 8 | DO1: ACCRUALS - Description 9 | DP1: ACCRUALS - Amount 9 | DQ1: ACCRUALS - Cumul. 9 | DR1: ACCRUALS - Description 10 | DS1: ACCRUALS - Amount 10 | DT1: ACCRUALS - Cumul. 10 | DU1: EI Hours | DV1: EMPLOYER CONTRIBUTION - Description 1 | DW1: EMPLOYER CONTRIBUTION - Hrs 1 | DX1: EMPLOYER CONTRIBUTION - Rate 1 | DY1: EMPLOYER CONTRIBUTION - Amount 1 | DZ1: EMPLOYER CONTRIBUTION - Cumul. 1 | EA1: EMPLOYER CONTRIBUTION - Description 2 | EB1: EMPLOYER CONTRIBUTION - Hrs 2 | EC1: EMPLOYER CONTRIBUTION - Rate 2 | ED1: EMPLOYER CONTRIBUTION - Amount 2 | EE1: EMPLOYER CONTRIBUTION - Cumul. 2 | EF1: EMPLOYER CONTRIBUTION - Description 3 | EG1: EMPLOYER CONTRIBUTION - Hrs 3 | EH1: EMPLOYER CONTRIBUTION - Rate 3 | EI1: EMPLOYER CONTRIBUTION - Amount 3 | EJ1: EMPLOYER CONTRIBUTION - Cumul. 3 | EK1: EMPLOYER CONTRIBUTION - Description 4 | EL1: EMPLOYER CONTRIBUTION - Hrs 4 | EM1: EMPLOYER CONTRIBUTION - Rate 4 | EN1: EMPLOYER CONTRIBUTION - Amount 4 | EO1: EMPLOYER CONTRIBUTION - Cumul. 4 | EP1: EMPLOYER CONTRIBUTION - Description 5 | EQ1: EMPLOYER CONTRIBUTION - Hrs 5 | ER1: EMPLOYER CONTRIBUTION - Rate 5 | ES1: EMPLOYER CONTRIBUTION - Amount 5 | ET1: EMPLOYER CONTRIBUTION - Cumul. 5 | EU1: EMPLOYER CONTRIBUTION - Description 6 | EV1: EMPLOYER CONTRIBUTION - Hrs 6 | EW1: EMPLOYER CONTRIBUTION - Rate 6 | EX1: EMPLOYER CONTRIBUTION - Amount 6 | EY1: EMPLOYER CONTRIBUTION - Cumul. 6 | EZ1: EMPLOYER CONTRIBUTION - Description 7 | FA1: EMPLOYER CONTRIBUTION - Hrs 7 | FB1: EMPLOYER CONTRIBUTION - Rate 7 | FC1: EMPLOYER CONTRIBUTION - Amount 7 | FD1: EMPLOYER CONTRIBUTION - Cumul. 7 | FE1: EMPLOYER CONTRIBUTION - Description 8 | FF1: EMPLOYER CONTRIBUTION - Hrs 8 | FG1: EMPLOYER CONTRIBUTION - Rate 8 | FH1: EMPLOYER CONTRIBUTION - Amount 8 | FI1: EMPLOYER CONTRIBUTION - Cumul. 8 | FJ1: EMPLOYER CONTRIBUTION - Description 9 | FK1: EMPLOYER CONTRIBUTION - Hrs 9 | FL1: EMPLOYER CONTRIBUTION - Rate 9 | FM1: EMPLOYER CONTRIBUTION - Amount 9 | FN1: EMPLOYER CONTRIBUTION - Cumul. 9 | FO1: EMPLOYER CONTRIBUTION - Description 10 | FP1: EMPLOYER CONTRIBUTION - Hrs 10 | FQ1: EMPLOYER CONTRIBUTION - Rate 10 | FR1: EMPLOYER CONTRIBUTION - Amount 10 | FS1: EMPLOYER CONTRIBUTION - Cumul. 10 | FT1: EMPLOYEE BENEFIT - Description | FU1: EMPLOYEE BENEFIT - Amount | FV1: EMPLOYEE BENEFIT - Cumul.
A2: 134 2024 23 Jul - 05 Aug TT003576_202416_1.pdf | B2: 16 | C2: 1-10 | D2: Thornton Tomasetti Canada Inc | E2: 116 Spadina Ave. Suite 301 Toronto Ontario Canada M5V 2K6 | F2: Ruvimbo Chikowero | G2: 301-116 Spadina Avenue Toronto, Ontario M5V 2K6 | H2: 010-06552 ***336 | I2: 2312.5 | J2: TT003576 | K2: 45486 | L2: 45499 | M2: Digital Design Technologist | N2: 45506 | O2: Annual Bonus | P2: 0 | Q2: 0 | R2: 0 | S2: 5000 | T2: Salary Regular Earning | U2: 80 | V2: 42.16 | W2: 3373.07 | X2: 52792.28 | BM2: CPP Premium | BN2: 193.3 | BO2: 3319.67 | BP2: EI Premium | BQ2: 55.99 | BR2: 959.31 | BS2: Federal Tax | BT2: 617.2 | BU2: 11026.72 | BV2: Group Insurance Premium | BW2: 6.67 | BX2: 100.05 | BY2: Insurance - L.T.D Premium | BZ2: 18.76 | CA2: 266.3 | CB2: RRSP - EE % | CC2: 168.65 | CD2: 2639.63 | DU2: 80.00 | DV2: DPSP - ER % | DW2: 0 | DX2: 0 | DY2: 168.65 | DZ2: 2639.63 | EA2: Insurance ER - AD&D | EB2: 0 | EC2: 0 | ED2: 2.7 | EE2: 40.5 | EF2: Insurance ER - Life | EG2: 0 | EH2: 0 | EI2: 7.56 | EJ2: 113.4 | FT2: not used | FU2: not used | FV2: not used
A3: 135 2024 06 Aug - 19 Aug TT003576_202417_1.pdf | B3: 17 | C3: 1-10 | D3: Thornton Tomasetti Canada Inc | E3: 116 Spadina Ave. Suite 301 Toronto Ontario Canada M5V 2K6 | F3: Ruvimbo Chikowero | G3: 301-116 Spadina Avenue Toronto, Ontario M5V 2K6 | H3: 010-06552 ***336 | I3: 2312.5 | J3: TT003576 | K3: 45500 | L3: 45513 | M3: Digital Design Technologist | N3: 45520 | O3: Annual Bonus | P3: 0 | Q3: 0 | R3: 0 | S3: 5000 | T3: Salary Regular Earning | U3: 80 | V3: 42.16 | W3: 3373.07 | X3: 56165.35 | BM3: CPP Premium | BN3: 193.3 | BO3: 3512.97 | BP3: EI Premium | BQ3: 55.99 | BR3: 1015.3 | BS3: Federal Tax | BT3: 617.2 | BU3: 11643.92 | BV3: Group Insurance Premium | BW3: 6.67 | BX3: 106.72 | BY3: Insurance - L.T.D Premium | BZ3: 18.76 | CA3: 285.06 | CB3: RRSP - EE % | CC3: 168.65 | CD3: 2808.28 | DU3: 80.00 | DV3: DPSP - ER % | DW3: 0 | DX3: 0 | DY3: 168.65 | DZ3: 2808.28 | EA3: Insurance ER - AD&D | EB3: 0 | EC3: 0 | ED3: 2.7 | EE3: 43.2 | EF3: Insurance ER - Life | EG3: 0 | EH3: 0 | EI3: 7.56 | EJ3: 120.96 | FT3: not used | FU3: not used | FV3: not used
A4: 136 2024 20 Aug - 02 Sep TT003576_202418_1.pdf | B4: 18 | C4: 1-10 | D4: Thornton Tomasetti Canada Inc | E4: 116 Spadina Ave. Suite 301 Toronto Ontario Canada M5V 2K6 | F4: Ruvimbo Chikowero | G4: 301-116 Spadina Avenue Toronto, Ontario M5V 2K6 | H4: 010-06552 ***336 | I4: 2363.72 | J4: TT003576 | K4: 45514 | L4: 45527 | M4: Digital Design Technologist | N4: 45534 | O4: Annual Bonus | P4: 0 | Q4: 0 | R4: 0 | S4: 5000 | T4: Salary Regular Earning | U4: 80 | V4: 42.16 | W4: 3373.07 | X4: 59538.42 | BM4: CPP Premium | BN4: 192.69 | BO4: 3705.66 | BP4: EI Premium | BQ4: 33.82 | BR4: 1049.12 | BS4: Federal Tax | BT4: 614.19 | BU4: 12258.11 | BV4: Group Insurance Premium | BW4: 0 | BX4: 106.72 | BY4: Insurance - L.T.D Premium | BZ4: 0 | CA4: 285.06 | CB4: RRSP - EE % | CC4: 168.65 | CD4: 2976.93 | DU4: 80.00 | DV4: DPSP - ER % | DW4: 0 | DX4: 0 | DY4: 168.65 | DZ4: 2976.93 | EA4: Insurance ER - AD&D | EB4: 0 | EC4: 0 | ED4: 0 | EE4: 43.2 | EF4: Insurance ER - Life | EG4: 0 | EH4: 0 | EI4: 0 | EJ4: 120.96 | FT4: not used | FU4: not used | FV4: not used
A5: 137 2024 03 Sep - 16 Sep TT003576_202419_1.pdf | B5: 19 | C5: 1-10 | D5: Thornton Tomasetti Canada Inc | E5: 116 Spadina Ave. Suite 301 Toronto Ontario Canada M5V 2K6 | F5: Ruvimbo Chikowero | G5: 301-116 Spadina Avenue Toronto, Ontario M5V 2K6 | H5: 010-06552 ***336 | I5: 2397.37 | J5: TT003576 | K5: 45528 | L5: 45541 | M5: Digital Design Technologist | N5: 45548 | O5: Annual Bonus | P5: 0 | Q5: 0 | R5: 0 | S5: 5000 | T5: Salary Regular Earning | U5: 80 | V5: 42.16 | W5: 3373.07 | X5: 62911.49 | BM5: CPP Premium | BN5: 161.84 | BO5: 3867.5 | BP5: EI Premium | BQ5: 0 | BR5: 1049.12 | BS5: Federal Tax | BT5: 618.61 | BU5: 12876.72 | BV5: Group Insurance Premium | BW5: 6.67 | BX5: 113.39 | BY5: Insurance - L.T.D Premium | BZ5: 19.93 | CA5: 304.99 | CB5: RRSP - EE % | CC5: 168.65 | CD5: 3145.58 | DU5: 80.00 | DV5: DPSP - ER % | DW5: 0 | DX5: 0 | DY5: 168.65 | DZ5: 3145.58 | EA5: Insurance ER - AD&D | EB5: 0 | EC5: 0 | ED5: 2.7 | EE5: 45.9 | EF5: Insurance ER - Life | EG5: 0 | EH5: 0 | EI5: 7.02 | EJ5: 127.98 | FT5: not used | FU5: not used | FV5: not used
A6: 138 2024 17 Sep - 30 Sep TT003576_202420_1.pdf | B6: 20 | C6: 1-10 | D6: Thornton Tomasetti Canada Inc | E6: 116 Spadina Ave. Suite 301 Toronto Ontario Canada M5V 2K6 | F6: Ruvimbo Chikowero | G6: 301-116 Spadina Avenue Toronto, Ontario M5V 2K6 | H6: 010-06552 ***336 | I6: 2466.57 | J6: TT003576 | K6: 45542 | L6: 45555 | M6: Digital Design Technologist | N6: 45562 | O6: Annual Bonus | P6: 0 | Q6: 0 | R6: 0 | S6: 5000 | T6: Salary Regular Earning | U6: 80 | V6: 42.16 | W6: 3373.07 | X6: 66284.56 | BM6: CPP Premium | BN6: 0 | BO6: 3867.5 | BP6: CPP Second Contribution | BQ6: 118.73 | BR6: 118.73 | BS6: EI Premium | BT6: 0 | BU6: 1049.12 | BV6: Federal Tax | BW6: 591.47 | BX6: 13468.19 | BY6: Group Insurance Premium | BZ6: 7.72 | CA6: 121.11 | CB6: Insurance - L.T.D Premium | CC6: 19.93 | CD6: 324.92 | CE6: RRSP - EE % | CF6: 168.65 | CG6: 3314.23 | DU6: 80.00 | DV6: DPSP - ER % | DW6: 0 | DX6: 0 | DY6: 168.65 | DZ6: 3314.23 | EA6: Insurance ER - AD&D | EB6: 0 | EC6: 0 | ED6: 2.7 | EE6: 48.6 | EF6: Insurance ER - Life | EG6: 0 | EH6: 0 | EI6: 7.02 | EJ6: 135 | FT6: not used | FU6: not used | FV6: not used
A7: 139 2024 01 Oct - 14 Oct TT003576_202421_1.pdf | B7: 21 | C7: 1-10 | D7: Thornton Tomasetti Canada Inc | E7: 116 Spadina Ave. Suite 301 Toronto Ontario Canada M5V 2K6 | F7: Ruvimbo Chikowero | G7: 301-116 Spadina Avenue Toronto, Ontario M5V 2K6 | H7: 010-06552 ***336 | I7: 2502.06 | J7: TT003576 | K7: 45556 | L7: 45569 | M7: Digital Design Technologist | N7: 45576 | O7: Annual Bonus | P7: 0 | Q7: 0 | R7: 0 | S7: 5000 | T7: Salary Regular Earning | U7: 80 | V7: 42.16 | W7: 3373.07 | X7: 69657.63 | BM7: CPP Premium | BN7: 0 | BO7: 3867.5 | BP7: CPP Second Contribution | BQ7: 69.27 | BR7: 188 | BS7: EI Premium | BT7: 0 | BU7: 1049.12 | BV7: Federal Tax | BW7: 606.14 | BX7: 14074.33 | BY7: Group Insurance Premium | BZ7: 7.02 | CA7: 128.13 | CB7: Insurance - L.T.D Premium | CC7: 19.93 | CD7: 344.85 | CE7: RRSP - EE % | CF7: 168.65 | CG7: 3482.88 | DU7: 80.00 | DV7: DPSP - ER % | DW7: 0 | DX7: 0 | DY7: 168.65 | DZ7: 3482.88 | EA7: Insurance ER - AD&D | EB7: 0 | EC7: 0 | ED7: 2.7 | EE7: 51.3 | EF7: Insurance ER - Life | EG7: 0 | EH7: 0 | EI7: 7.02 | EJ7: 142.02 | FT7: not used | FU7: not used | FV7: not used
A8: 140 2024 15 Oct - 28 Oct TT003576_202422_1.pdf | B8: 22 | C8: 1-10 | D8: Thornton Tomasetti Canada Inc | E8: 116 Spadina Ave. Suite 301 Toronto Ontario Canada M5V 2K6 | F8: Ruvimbo Chikowero | G8: 301-116 Spadina Avenue Toronto, Ontario M5V 2K6 | H8: 010-06552 ***336 | I8: 2550.8 | J8: TT003576 | K8: 45570 | L8: 45583 | M8: Digital Design Technologist | N8: 45590 | O8: Annual Bonus | P8: 0 | Q8: 0 | R8: 0 | S8: 5000 | T8: Salary Regular Earning | U8: 80 | V8: 42.16 | W8: 3373.07 | X8: 73030.7 | BM8: CPP Premium | BN8: 0 | BO8: 3867.5 | BP8: CPP Second Contribution | BQ8: 0 | BR8: 188 | BS8: EI Premium | BT8: 0 | BU8: 1049.12 | BV8: Federal Tax | BW8: 626.67 | BX8: 14701 | BY8: Group Insurance Premium | BZ8: 7.02 | CA8: 135.15 | CB8: Insurance - L.T.D Premium | CC8: 19.93 | CD8: 364.78 | CE8: RRSP - EE % | CF8: 168.65 | CG8: 3651.53 | DU8: 80.00 | DV8: DPSP - ER % | DW8: 0 | DX8: 0 | DY8: 168.65 | DZ8: 3651.53 | EA8: Insurance ER - AD&D | EB8: 0 | EC8: 0 | ED8: 2.7 | EE8: 54 | EF8: Insurance ER - Life | EG8: 0 | EH8: 0 | EI8: 7.02 | EJ8: 149.04 | FT8: not used | FU8: not used | FV8: not used
A9: 141 2024 29 Oct - 11 Nov TT003576_202423_1.pdf | B9: 23 | C9: 1-10 | D9: Thornton Tomasetti Canada Inc | E9: 116 Spadina Ave. Suite 301 Toronto Ontario Canada M5V 2K6 | F9: Ruvimbo Chikowero | G9: 301-116 Spadina Avenue Toronto, Ontario M5V 2K6 | H9: 010-06552 ***336 | I9: 2550.8 | J9: TT003576 | K9: 45584 | L9: 45597 | M9: Digital Design Technologist | N9: 45604 | O9: Annual Bonus | P9: 0 | Q9: 0 | R9: 0 | S9: 5000 | T9: Salary Regular Earning | U9: 80 | V9: 42.16 | W9: 3373.07 | X9: 76403.77 | BM9: CPP Premium | BN9: 0 | BO9: 3867.5 | BP9: CPP Second Contribution | BQ9: 0 | BR9: 188 | BS9: EI Premium | BT9: 0 | BU9: 1049.12 | BV9: Federal Tax | BW9: 626.67 | BX9: 15327.67 | BY9: Group Insurance Premium | BZ9: 7.02 | CA9: 142.17 | CB9: Insurance - L.T.D Premium | CC9: 19.93 | CD9: 384.71 | CE9: RRSP - EE % | CF9: 168.65 | CG9: 3820.18 | DU9: 80.00 | DV9: DPSP - ER % | DW9: 0 | DX9: 0 | DY9: 168.65 | DZ9: 3820.18 | EA9: Insurance ER - AD&D | EB9: 0 | EC9: 0 | ED9: 2.7 | EE9: 56.7 | EF9: Insurance ER - Life | EG9: 0 | EH9: 0 | EI9: 7.02 | EJ9: 156.06 | FT9: not used | FU9: not used | FV9: not used
A10: 142 2024 12 Nov - 25 Nov TT003576_202424_1.pdf | B10: 24 | C10: 1-10 | D10: Thornton Tomasetti Canada Inc | E10: 116 Spadina Ave. Suite 301 Toronto Ontario Canada M5V 2K6 | F10: Ruvimbo Chikowero | G10: 301-116 Spadina Avenue Toronto, Ontario M5V 2K6 | H10: 010-06552 ***336 | I10: 2831.48 | J10: TT003576 | K10: 45598 | L10: 45611 | M10: Digital Design Technologist | N10: 45618 | O10: Annual Bonus | P10: 0 | Q10: 0 | R10: 0 | S10: 5000 | T10: Fitness allowance | U10: 0 | V10: 0 | W10: 400 | X10: 400 | Y10: Salary Regular Earning | Z10: 80 | AA10: 42.16 | AB10: 3373.07 | AC10: 79776.84 | BM10: CPP Premium | BN10: 0 | BO10: 3867.5 | BP10: CPP Second Contribution | BQ10: 0 | BR10: 188 | BS10: EI Premium | BT10: 0 | BU10: 1049.12 | BV10: Federal Tax | BW10: 745.99 | BX10: 16073.66 | BY10: Group Insurance Premium | BZ10: 7.02 | CA10: 149.19 | CB10: Insurance - L.T.D Premium | CC10: 19.93 | CD10: 404.64 | CE10: RRSP - EE % | CF10: 168.65 | CG10: 3988.83 | DU10: 80.00 | DV10: DPSP - ER % | DW10: 0 | DX10: 0 | DY10: 168.65 | DZ10: 3988.83 | EA10: Insurance ER - AD&D | EB10: 0 | EC10: 0 | ED10: 2.7 | EE10: 59.4 | EF10: Insurance ER - Life | EG10: 0 | EH10: 0 | EI10: 7.02 | EJ10: 163.08 | FT10: not used | FU10: not used | FV10: not used
A11: 143 2024 26 Nov - 09 Dec TT003576_202425_1.pdf | B11: 25 | C11: 1-10 | D11: Thornton Tomasetti Canada Inc | E11: 116 Spadina Ave. Suite 301 Toronto Ontario Canada M5V 2K6 | F11: Ruvimbo Chikowero | G11: 301-116 Spadina Avenue Toronto, Ontario M5V 2K6 | H11: 010-06552 ***336 | I11: 2550.8 | J11: TT003576 | K11: 45612 | L11: 45625 | M11: Digital Design Technologist | N11: 45632 | O11: Annual Bonus | P11: 0 | Q11: 0 | R11: 0 | S11: 5000 | T11: Fitness allowance | U11: 0 | V11: 0 | W11: 0 | X11: 400 | Y11: Salary Regular Earning | Z11: 80 | AA11: 42.16 | AB11: 3373.07 | AC11: 83149.91 | BM11: CPP Premium | BN11: 0 | BO11: 3867.5 | BP11: CPP Second Contribution | BQ11: 0 | BR11: 188 | BS11: EI Premium | BT11: 0 | BU11: 1049.12 | BV11: Federal Tax | BW11: 626.67 | BX11: 16700.33 | BY11: Group Insurance Premium | BZ11: 7.02 | CA11: 156.21 | CB11: Insurance - L.T.D Premium | CC11: 19.93 | CD11: 424.57 | CE11: RRSP - EE % | CF11: 168.65 | CG11: 4157.48 | DU11: 80.00 | DV11: DPSP - ER % | DW11: 0 | DX11: 0 | DY11: 168.65 | DZ11: 4157.48 | EA11: Insurance ER - AD&D | EB11: 0 | EC11: 0 | ED11: 2.7 | EE11: 62.1 | EF11: Insurance ER - Life | EG11: 0 | EH11: 0 | EI11: 7.02 | EJ11: 170.1 | FT11: not used | FU11: not used | FV11: not used
A12: 144 2024 10 Dec - 23 Dec TT003576_202426_1.pdf | B12: 26 | C12: 1-10 | D12: Thornton Tomasetti Canada Inc | E12: 116 Spadina Ave. Suite 301 Toronto Ontario Canada M5V 2K6 | F12: Ruvimbo Chikowero | G12: 301-116 Spadina Avenue Toronto, Ontario M5V 2K6 | H12: 010-06552 ***336 | I12: 2550.8 | J12: TT003576 | K12: 45626 | L12: 45639 | M12: Digital Design Technologist | N12: 45646 | O12: Annual Bonus | P12: 0 | Q12: 0 | R12: 0 | S12: 5000 | T12: Fitness allowance | U12: 0 | V12: 0 | W12: 0 | X12: 400 | Y12: Salary Regular Earning | Z12: 80 | AA12: 42.16 | AB12: 3373.07 | AC12: 86522.98 | BM12: CPP Premium | BN12: 0 | BO12: 3867.5 | BP12: CPP Second Contribution | BQ12: 0 | BR12: 188 | BS12: EI Premium | BT12: 0 | BU12: 1049.12 | BV12: Federal Tax | BW12: 626.67 | BX12: 17327 | BY12: Group Insurance Premium | BZ12: 7.02 | CA12: 163.23 | CB12: Insurance - L.T.D Premium | CC12: 19.93 | CD12: 444.5 | CE12: RRSP - EE % | CF12: 168.65 | CG12: 4326.13 | DU12: 80.00 | DV12: DPSP - ER % | DW12: 0 | DX12: 0 | DY12: 168.65 | DZ12: 4326.13 | EA12: Insurance ER - AD&D | EB12: 0 | EC12: 0 | ED12: 2.7 | EE12: 64.8 | EF12: Insurance ER - Life | EG12: 0 | EH12: 0 | EI12: 7.02 | EJ12: 177.12 | FT12: not used | FU12: not used | FV12: not used
A13: 145 2024 24 Dec - 2025 06 Jan TT003576_202501_1.pdf | B13: 1 | C13: 1-10 | D13: Thornton Tomasetti Canada Inc | E13: 116 Spadina Ave. Suite 301 Toronto Ontario Canada M5V 2K6 | F13: Ruvimbo Chikowero | G13: 301-116 Spadina Avenue Toronto, Ontario M5V 2K6 | H13: 010-06552 ***336 | I13: 2311.17 | J13: TT003576 | K13: 45650 | L13: 45663 | M13: Digital Design Technologist | N13: 45660 | O13: Salary Regular Earning | P13: 80 | Q13: 42.16 | R13: 3373.07 | S13: 3373.07 | BM13: CPP Premium | BN13: 193.27 | BO13: 193.27 | BP13: EI Premium | BQ13: 55.99 | BR13: 55.99 | BS13: Federal Tax | BT13: 617.04 | BU13: 617.04 | BV13: Group Insurance Premium | BW13: 7.02 | BX13: 7.02 | BY13: Insurance - L.T.D Premium | BZ13: 19.93 | CA13: 19.93 | CB13: RRSP - EE % | CC13: 168.65 | CD13: 168.65 | DU13: 80.00 | DV13: DPSP - ER % | DW13: 0 | DX13: 0 | DY13: 168.65 | DZ13: 168.65 | EA13: Insurance ER - AD&D | EB13: 0 | EC13: 0 | ED13: 2.7 | EE13: 2.7 | EF13: Insurance ER - Life | EG13: 0 | EH13: 0 | EI13: 7.02 | EJ13: 7.02 | FT13: not used | FU13: not used | FV13: not used
A14: 146 2025 07 Jan - 20 Jan TT003576_202502_1.pdf | B14: 2 | C14: 1-10 | D14: Thornton Tomasetti Canada Inc | E14: 116 Spadina Ave. Suite 301 Toronto Ontario Canada M5V 2K6 | F14: Ruvimbo Chikowero | G14: 301-116 Spadina Avenue Toronto, Ontario M5V 2K6 | H14: 010-06552 ***336 | I14: 2321.93 | J14: TT003576 | K14: 45654 | L14: 45667 | M14: Digital Design Technologist | N14: 45674 | O14: Salary Regular Earning | P14: 80 | Q14: 42.16 | R14: 3373.07 | S14: 6746.14 | BM14: CPP Premium | BN14: 193.27 | BO14: 386.54 | BP14: EI Premium | BQ14: 55.32 | BR14: 111.31 | BS14: Federal Tax | BT14: 606.95 | BU14: 1223.99 | BV14: Group Insurance Premium | BW14: 7.02 | BX14: 14.04 | BY14: Insurance - L.T.D Premium | BZ14: 19.93 | CA14: 39.86 | CB14: RRSP - EE % | CC14: 168.65 | CD14: 337.3 | DU14: 80.00 | DV14: DPSP - ER % | DW14: 0 | DX14: 0 | DY14: 168.65 | DZ14: 337.3 | EA14: Insurance ER - AD&D | EB14: 0 | EC14: 0 | ED14: 2.7 | EE14: 5.4 | EF14: Insurance ER - Life | EG14: 0 | EH14: 0 | EI14: 7.02 | EJ14: 14.04 | FT14: not used | FU14: not used | FV14: not used
A15: 147 21 Jan 2025 - 03 Feb 2025 TT003576_202503_1.pdf | B15: 3 | C15: 1-10 | D15: Thornton Tomasetti Canada Inc | E15: 116 Spadina Ave. Suite 301 Toronto Ontario Canada M5V 2K6 | F15: Ruvimbo Chikowero | G15: 301-116 Spadina Avenue Toronto, Ontario M5V 2K6 | H15: 010-06552 ***336 | I15: 2352.31 | J15: TT003576 | K15: 45668 | L15: 45681 | M15: Digital Design Technologist | N15: 45688 | O15: Salary Regular Earning | P15: 80 | Q15: 42.16 | R15: 3373.07 | S15: 10119.21 | BM15: CPP Premium | BN15: 192.69 | BO15: 579.23 | BP15: EI Premium | BQ15: 55.32 | BR15: 166.63 | BS15: Federal Tax | BT15: 604.1 | BU15: 1828.09 | BV15: Group Insurance Premium | BW15: 0 | BX15: 14.04 | BY15: Insurance - L.T.D Premium | BZ15: 0 | CA15: 39.86 | CB15: RRSP - EE % | CC15: 168.65 | CD15: 505.95 | DU15: 80.00 | DV15: DPSP - ER % | DW15: 0 | DX15: 0 | DY15: 168.65 | DZ15: 505.95 | EA15: Insurance ER - AD&D | EB15: 0 | EC15: 0 | ED15: 0 | EE15: 5.4 | EF15: Insurance ER - Life | EG15: 0 | EH15: 0 | EI15: 0 | EJ15: 14.04 | FT15: not used | FU15: not used | FV15: not used
A16: 148 04 Feb 2025 - 17 Feb 2025 TT003576_202504_1.pdf | B16: 4 | C16: 1-10 | D16: Thornton Tomasetti Canada Inc | E16: 116 Spadina Ave. Suite 301 Toronto Ontario Canada M5V 2K6 | F16: Ruvimbo Chikowero | G16: 301-116 Spadina Avenue Toronto, Ontario M5V 2K6 | H16: 010-06552 ***336 | I16: 2321.93 | J16: TT003576 | K16: 45682 | L16: 45695 | M16: Digital Design Technologist | N16: 45702 | O16: Salary Regular Earning | P16: 80 | Q16: 42.16 | R16: 3373.07 | S16: 13492.28 | BM16: CPP Premium | BN16: 193.27 | BO16: 772.5 | BP16: EI Premium | BQ16: 55.32 | BR16: 221.95 | BS16: Federal Tax | BT16: 606.95 | BU16: 2435.04 | BV16: Group Insurance Premium | BW16: 7.02 | BX16: 21.06 | BY16: Insurance - L.T.D Premium | BZ16: 19.93 | CA16: 59.79 | CB16: RRSP - EE % | CC16: 168.65 | CD16: 674.6 | DU16: 80.00 | DV16: DPSP - ER % | DW16: 0 | DX16: 0 | DY16: 168.65 | DZ16: 674.6 | EA16: Insurance ER - AD&D | EB16: 0 | EC16: 0 | ED16: 2.7 | EE16: 8.1 | EF16: Insurance ER - Life | EG16: 0 | EH16: 0 | EI16: 7.02 | EJ16: 21.06 | FT16: not used | FU16: not used | FV16: not used
A17: 149 18 Feb 2025 - 03 Mar 2025 TT003576_202505_1.pdf | B17: 5 | C17: 1-10 | D17: Thornton Tomasetti Canada Inc | E17: 116 Spadina Ave. Suite 301 Toronto Ontario Canada M5V 2K6 | F17: Ruvimbo Chikowero | G17: 301-116 Spadina Avenue Toronto, Ontario M5V 2K6 | H17: 010-06552 ***336 | I17: 2321.93 | J17: TT003576 | K17: 45696 | L17: 45709 | M17: Digital Design Technologist | N17: 45716 | O17: Salary Regular Earning | P17: 80 | Q17: 42.16 | R17: 3373.07 | S17: 16865.35 | BM17: CPP Premium | BN17: 193.27 | BO17: 965.77 | BP17: EI Premium | BQ17: 55.32 | BR17: 277.27 | BS17: Federal Tax | BT17: 606.95 | BU17: 3041.99 | BV17: Group Insurance Premium | BW17: 7.02 | BX17: 28.08 | BY17: Insurance - L.T.D Premium | BZ17: 19.93 | CA17: 79.72 | CB17: RRSP - EE % | CC17: 168.65 | CD17: 843.25 | DU17: 80.00 | DV17: DPSP - ER % | DW17: 0 | DX17: 0 | DY17: 168.65 | DZ17: 843.25 | EA17: Insurance ER - AD&D | EB17: 0 | EC17: 0 | ED17: 2.7 | EE17: 10.8 | EF17: Insurance ER - Life | EG17: 0 | EH17: 0 | EI17: 7.02 | EJ17: 28.08 | FT17: not used | FU17: not used | FV17: not used
A18: 150 04 Mar 2025 - 17 Mar 2025 TT003576_202506_1.pdf | B18: 6 | C18: 1-10 | D18: Thornton Tomasetti Canada Inc | E18: 116 Spadina Ave. Suite 301 Toronto Ontario Canada M5V 2K6 | F18: Ruvimbo Chikowero | G18: 301-116 Spadina Avenue Toronto, Ontario M5V 2K6 | H18: 010-06552 ***336 | I18: 2321.93 | J18: TT003576 | K18: 45710 | L18: 45723 | M18: Digital Design Technologist | N18: 45730 | O18: Salary Regular Earning | P18: 80 | Q18: 42.16 | R18: 3373.07 | S18: 20238.42 | BM18: CPP Premium | BN18: 193.27 | BO18: 1159.04 | BP18: EI Premium | BQ18: 55.32 | BR18: 332.59 | BS18: Federal Tax | BT18: 606.95 | BU18: 3648.94 | BV18: Group Insurance Premium | BW18: 7.02 | BX18: 35.1 | BY18: Insurance - L.T.D Premium | BZ18: 19.93 | CA18: 99.65 | CB18: RRSP - EE % | CC18: 168.65 | CD18: 1011.9 | DU18: 80.00 | DV18: DPSP - ER % | DW18: 0 | DX18: 0 | DY18: 168.65 | DZ18: 1011.9 | EA18: Insurance ER - AD&D | EB18: 0 | EC18: 0 | ED18: 2.7 | EE18: 13.5 | EF18: Insurance ER - Life | EG18: 0 | EH18: 0 | EI18: 7.02 | EJ18: 35.1 | FT18: not used | FU18: not used | FV18: not used
A19: 151 18 Mar 2025 - 31 Mar 2025 TT003576_202507_1.pdf | B19: 7 | C19: 1-10 | D19: Thornton Tomasetti Canada Inc | E19: 116 Spadina Ave. Suite 301 Toronto Ontario Canada M5V 2K6 | F19: Ruvimbo Chikowero | G19: 301-116 Spadina Avenue Toronto, Ontario M5V 2K6 | H19: 010-06552 ***336 | I19: 2321.93 | J19: TT003576 | K19: 45724 | L19: 45737 | M19: Digital Design Technologist | N19: 45744 | O19: Salary Regular Earning | P19: 80 | Q19: 42.16 | R19: 3373.07 | S19: 23611.49 | BM19: CPP Premium | BN19: 193.27 | BO19: 1352.31 | BP19: EI Premium | BQ19: 55.32 | BR19: 387.91 | BS19: Federal Tax | BT19: 606.95 | BU19: 4255.89 | BV19: Group Insurance Premium | BW19: 7.02 | BX19: 42.12 | BY19: Insurance - L.T.D Premium | BZ19: 19.93 | CA19: 119.58 | CB19: RRSP - EE % | CC19: 168.65 | CD19: 1180.55 | DU19: 80.00 | DV19: DPSP - ER % | DW19: 0 | DX19: 0 | DY19: 168.65 | DZ19: 1180.55 | EA19: Insurance ER - AD&D | EB19: 0 | EC19: 0 | ED19: 2.7 | EE19: 16.2 | EF19: Insurance ER - Life | EG19: 0 | EH19: 0 | EI19: 7.02 | EJ19: 42.12 | FT19: not used | FU19: not used | FV19: not used
A20: 152 01 Apr 2025 - 14 Apr 2025 TT003576_202508_1.pdf | B20: 8 | C20: 1-10 | D20: Thornton Tomasetti Canada Inc | E20: 116 Spadina Ave. Suite 301 Toronto Ontario Canada M5V 2K6 | F20: Ruvimbo Chikowero | G20: 301-116 Spadina Avenue Toronto, Ontario M5V 2K6 | H20: 010-06552 ***336 | I20: 2321.93 | J20: TT003576 | K20: 45738 | L20: 45751 | M20: Digital Design Technologist | N20: 45758 | O20: Salary Regular Earning | P20: 80 | Q20: 42.16 | R20: 3373.07 | S20: 26984.56 | BM20: CPP Premium | BN20: 193.27 | BO20: 1545.58 | BP20: EI Premium | BQ20: 55.32 | BR20: 443.23 | BS20: Federal Tax | BT20: 606.95 | BU20: 4862.84 | BV20: Group Insurance Premium | BW20: 7.02 | BX20: 49.14 | BY20: Insurance - L.T.D Premium | BZ20: 19.93 | CA20: 139.51 | CB20: RRSP - EE % | CC20: 168.65 | CD20: 1349.2 | DU20: 80.00 | DV20: DPSP - ER % | DW20: 0 | DX20: 0 | DY20: 168.65 | DZ20: 1349.2 | EA20: Insurance ER - AD&D | EB20: 0 | EC20: 0 | ED20: 2.7 | EE20: 18.9 | EF20: Insurance ER - Life | EG20: 0 | EH20: 0 | EI20: 7.02 | EJ20: 49.14 | FT20: not used | FU20: not used | FV20: not used
A21: 152 01 Apr 2025 - 14 Apr 2025 TT003576_202508_2 bonus.pdf | B21: 8 | C21: 2-30 | D21: Thornton Tomasetti Canada Inc | E21: 116 Spadina Ave. Suite 301 Toronto Ontario Canada M5V 2K6 | F21: Ruvimbo Chikowero | G21: 301-116 Spadina Avenue Toronto, Ontario M5V 2K6 | H21: 010-06552 ***336 | I21: 4314.85 | J21: TT003576 | K21: 45738 | L21: 45751 | M21: Digital Design Technologist | N21: 45758 | O21: Annual Bonus | P21: 0 | Q21: 0 | R21: 7020 | S21: 7020 | T21: Salary Regular Earning | U21: 0 | V21: 0 | W21: 0 | X21: 26984.56 | BM21: CPP Premium | BN21: 417.69 | BO21: 1963.27 | BP21: EI Premium | BQ21: 115.13 | BR21: 558.36 | BS21: Federal Tax | BT21: 2172.33 | BU21: 7035.17 | BV21: Group Insurance Premium | BW21: 0 | BX21: 49.14 | BY21: Insurance - L.T.D Premium | BZ21: 0 | CA21: 139.51 | CB21: RRSP - EE % | CC21: 0 | CD21: 1349.2 | DU21: 0.00 | DV21: DPSP - ER % | DW21: 0 | DX21: 0 | DY21: 0 | DZ21: 1349.2 | EA21: Insurance ER - AD&D | EB21: 0 | EC21: 0 | ED21: 0 | EE21: 18.9 | EF21: Insurance ER - Life | EG21: 0 | EH21: 0 | EI21: 0 | EJ21: 49.14 | FT21: not used | FU21: not used | FV21: not used
A22: 153 15 Apr 2025 - 28 Apr 2025 TT003576_202509_1.pdf | B22: 9 | C22: 1-10 | D22: Thornton Tomasetti Canada Inc | E22: 116 Spadina Ave. Suite 301 Toronto Ontario Canada M5V 2K6 | F22: Ruvimbo Chikowero | G22: 301-116 Spadina Avenue Toronto, Ontario M5V 2K6 | H22: 010-06552 ***336 | I22: 2321.93 | J22: TT003576 | K22: 45752 | L22: 45765 | M22: Digital Design Technologist | N22: 45772 | O22: Annual Bonus | P22: 0 | Q22: 0 | R22: 0 | S22: 7020 | T22: Salary Regular Earning | U22: 80 | V22: 42.16 | W22: 3373.07 | X22: 30357.63 | BM22: CPP Premium | BN22: 193.27 | BO22: 2156.54 | BP22: EI Premium | BQ22: 55.32 | BR22: 613.68 | BS22: Federal Tax | BT22: 606.95 | BU22: 7642.12 | BV22: Group Insurance Premium | BW22: 7.02 | BX22: 56.16 | BY22: Insurance - L.T.D Premium | BZ22: 19.93 | CA22: 159.44 | CB22: RRSP - EE % | CC22: 168.65 | CD22: 1517.85 | DU22: 80.00 | DV22: DPSP - ER % | DW22: 0 | DX22: 0 | DY22: 168.65 | DZ22: 1517.85 | EA22: Insurance ER - AD&D | EB22: 0 | EC22: 0 | ED22: 2.7 | EE22: 21.6 | EF22: Insurance ER - Life | EG22: 0 | EH22: 0 | EI22: 7.02 | EJ22: 56.16 | FT22: not used | FU22: not used | FV22: not used
A23: 154 29 Apr 2025 - 12 May 2025 TT003576_202510_1.pdf | B23: 10 | C23: 1-10 | D23: Thornton Tomasetti Canada Inc | E23: 116 Spadina Ave. Suite 301 Toronto Ontario Canada M5V 2K6 | F23: Ruvimbo Chikowero | G23: 301-116 Spadina Avenue Toronto, Ontario M5V 2K6 | H23: 010-06552 ***336 | I23: 2461.62 | J23: TT003576 | K23: 45766 | L23: 45779 | M23: Digital Design Technologist | N23: 45786 | O23: Annual Bonus | P23: 0 | Q23: 0 | R23: 0 | S23: 7020 | T23: Salary Regular Earning | U23: 80 | V23: 45.1 | W23: 3607.69 | X23: 33965.32 | BM23: CPP Premium | BN23: 207.23 | BO23: 2363.77 | BP23: EI Premium | BQ23: 59.17 | BR23: 672.85 | BS23: Federal Tax | BT23: 672.34 | BU23: 8314.46 | BV23: Group Insurance Premium | BW23: 7.02 | BX23: 63.18 | BY23: Insurance - L.T.D Premium | BZ23: 19.93 | CA23: 179.37 | CB23: RRSP - EE % | CC23: 180.38 | CD23: 1698.23 | DU23: 80.00 | DV23: DPSP - ER % | DW23: 0 | DX23: 0 | DY23: 180.38 | DZ23: 1698.23 | EA23: Insurance ER - AD&D | EB23: 0 | EC23: 0 | ED23: 2.7 | EE23: 24.3 | EF23: Insurance ER - Life | EG23: 0 | EH23: 0 | EI23: 7.02 | EJ23: 63.18 | FT23: not used | FU23: not used | FV23: not used
A24: 155 13 May 2025 - 26 May 2025 TT003576_202511_1.pdf | B24: 11 | C24: 1-10 | D24: Thornton Tomasetti Canada Inc | E24: 116 Spadina Ave. Suite 301 Toronto Ontario Canada M5V 2K6 | F24: Ruvimbo Chikowero | G24: 301-116 Spadina Avenue Toronto, Ontario M5V 2K6 | H24: 010-06552 ***336 | I24: 2461.62 | J24: TT003576 | K24: 45780 | L24: 45793 | M24: Digital Design Technologist | N24: 45800 | O24: Annual Bonus | P24: 0 | Q24: 0 | R24: 0 | S24: 7020 | T24: Salary Regular Earning | U24: 80 | V24: 45.1 | W24: 3607.69 | X24: 37573.01 | BM24: CPP Premium | BN24: 207.23 | BO24: 2571 | BP24: EI Premium | BQ24: 59.17 | BR24: 732.02 | BS24: Federal Tax | BT24: 672.34 | BU24: 8986.8 | BV24: Group Insurance Premium | BW24: 7.02 | BX24: 70.2 | BY24: Insurance - L.T.D Premium | BZ24: 19.93 | CA24: 199.3 | CB24: RRSP - EE % | CC24: 180.38 | CD24: 1878.61 | DU24: 80.00 | DV24: DPSP - ER % | DW24: 0 | DX24: 0 | DY24: 180.38 | DZ24: 1878.61 | EA24: Insurance ER - AD&D | EB24: 0 | EC24: 0 | ED24: 2.7 | EE24: 27 | EF24: Insurance ER - Life | EG24: 0 | EH24: 0 | EI24: 7.02 | EJ24: 70.2 | FT24: not used | FU24: not used | FV24: not used
A25: 156 27 May 2025 - 09 Jun 2025 TT003576_202512_1.pdf | B25: 12 | C25: 1-10 | D25: Thornton Tomasetti Canada Inc | E25: 116 Spadina Ave. Suite 301 Toronto Ontario Canada M5V 2K6 | F25: Ruvimbo Chikowero | G25: 301-116 Spadina Avenue Toronto, Ontario M5V 2K6 | H25: 010-06552 ***336 | I25: 2459.28 | J25: TT003576 | K25: 45794 | L25: 45807 | M25: Digital Design Technologist | N25: 45814 | O25: Annual Bonus | P25: 0 | Q25: 0 | R25: 0 | S25: 7020 | T25: Salary Regular Earning | U25: 80 | V25: 45.1 | W25: 3607.69 | X25: 41180.7 | BM25: CPP Premium | BN25: 207.23 | BO25: 2778.23 | BP25: EI Premium | BQ25: 59.17 | BR25: 791.19 | BS25: Federal Tax | BT25: 672.34 | BU25: 9659.14 | BV25: Group Insurance Premium | BW25: 7.02 | BX25: 77.22 | BY25: Insurance - L.T.D Premium | BZ25: 22.27 | CA25: 221.57 | CB25: RRSP - EE % | CC25: 180.38 | CD25: 2058.99 | DU25: 80.00 | DV25: DPSP - ER % | DW25: 0 | DX25: 0 | DY25: 180.38 | DZ25: 2058.99 | EA25: Insurance ER - AD&D | EB25: 0 | EC25: 0 | ED25: 2.7 | EE25: 29.7 | EF25: Insurance ER - Life | EG25: 0 | EH25: 0 | EI25: 7.02 | EJ25: 77.22 | FT25: not used | FU25: not used | FV25: not used
A26: 157 10 Jun 2025 - 23 Jun 2025 TT003576_202513_1.pdf | B26: 13 | C26: 1-10 | D26: Thornton Tomasetti Canada Inc | E26: 116 Spadina Ave. Suite 301 Toronto Ontario Canada M5V 2K6 | F26: Ruvimbo Chikowero | G26: 301-116 Spadina Avenue Toronto, Ontario M5V 2K6 | H26: 010-06552 ***336 | I26: 2459.28 | J26: TT003576 | K26: 45808 | L26: 45821 | M26: Digital Design Technologist | N26: 45828 | O26: Annual Bonus | P26: 0 | Q26: 0 | R26: 0 | S26: 7020 | T26: Salary Regular Earning | U26: 80 | V26: 45.1 | W26: 3607.69 | X26: 44788.39 | BM26: CPP Premium | BN26: 207.23 | BO26: 2985.46 | BP26: EI Premium | BQ26: 59.17 | BR26: 850.36 | BS26: Federal Tax | BT26: 672.34 | BU26: 10331.48 | BV26: Group Insurance Premium | BW26: 7.02 | BX26: 84.24 | BY26: Insurance - L.T.D Premium | BZ26: 22.27 | CA26: 243.84 | CB26: RRSP - EE % | CC26: 180.38 | CD26: 2239.37 | DU26: 80.00 | DV26: DPSP - ER % | DW26: 0 | DX26: 0 | DY26: 180.38 | DZ26: 2239.37 | EA26: Insurance ER - AD&D | EB26: 0 | EC26: 0 | ED26: 2.7 | EE26: 32.4 | EF26: Insurance ER - Life | EG26: 0 | EH26: 0 | EI26: 7.02 | EJ26: 84.24 | FT26: not used | FU26: not used | FV26: not used
A27: 158 24 Jun 2025 - 07 Jul 2025 TT003576_202514_1.pdf | B27: 14 | C27: 1-10 | D27: Thornton Tomasetti Canada Inc | E27: 116 Spadina Ave. Suite 301 Toronto Ontario Canada M5V 2K6 | F27: Ruvimbo Chikowero | G27: 301-116 Spadina Avenue Toronto, Ontario M5V 2K6 | H27: 010-06552 ***336 | I27: 2474.01 | J27: TT003576 | K27: 45822 | L27: 45835 | M27: Digital Design Technologist | N27: 45842 | O27: Annual Bonus | P27: 0 | Q27: 0 | R27: 0 | S27: 7020 | T27: Salary Regular Earning | U27: 80 | V27: 45.1 | W27: 3607.69 | X27: 48396.08 | BM27: CPP Premium | BN27: 207.23 | BO27: 3192.69 | BP27: EI Premium | BQ27: 59.17 | BR27: 909.53 | BS27: Federal Tax | BT27: 658.78 | BU27: 10990.26 | BV27: Group Insurance Premium | BW27: 7.02 | BX27: 91.26 | BY27: Insurance - L.T.D Premium | BZ27: 21.1 | CA27: 264.94 | CB27: RRSP - EE % | CC27: 180.38 | CD27: 2419.75 | DU27: 80.00 | DV27: DPSP - ER % | DW27: 0 | DX27: 0 | DY27: 180.38 | DZ27: 2419.75 | EA27: Insurance ER - AD&D | EB27: 0 | EC27: 0 | ED27: 2.7 | EE27: 35.1 | EF27: Insurance ER - Life | EG27: 0 | EH27: 0 | EI27: 7.02 | EJ27: 91.26 | FT27: not used | FU27: not used | FV27: not used
A28: 159 08 Jul 2025 - 21 Jul 2025 TT003576_202515_1.pdf | B28: 15 | C28: 1-10 | D28: Thornton Tomasetti Canada Inc | E28: 116 Spadina Ave. Suite 301 Toronto Ontario Canada M5V 2K6 | F28: Ruvimbo Chikowero | G28: 301-116 Spadina Avenue Toronto, Ontario M5V 2K6 | H28: 010-06552 ***336 | I28: 2474.01 | J28: TT003576 | K28: 45836 | L28: 45849 | M28: Digital Design Technologist | N28: 45856 | O28: Annual Bonus | P28: 0 | Q28: 0 | R28: 0 | S28: 7020 | T28: Salary Regular Earning | U28: 80 | V28: 45.1 | W28: 3607.69 | X28: 52003.77 | BM28: CPP Premium | BN28: 207.23 | BO28: 3399.92 | BP28: EI Premium | BQ28: 59.17 | BR28: 968.7 | BS28: Federal Tax | BT28: 658.78 | BU28: 11649.04 | BV28: Group Insurance Premium | BW28: 7.02 | BX28: 98.28 | BY28: Insurance - L.T.D Premium | BZ28: 21.1 | CA28: 286.04 | CB28: RRSP - EE % | CC28: 180.38 | CD28: 2600.13 | DU28: 80.00 | DV28: DPSP - ER % | DW28: 0 | DX28: 0 | DY28: 180.38 | DZ28: 2600.13 | EA28: Insurance ER - AD&D | EB28: 0 | EC28: 0 | ED28: 2.7 | EE28: 37.8 | EF28: Insurance ER - Life | EG28: 0 | EH28: 0 | EI28: 7.02 | EJ28: 98.28 | FT28: not used | FU28: not used | FV28: not used

Sheet Processed Data
C1: TOTALS | D1: =SUM(D3:D1048576) -> 67411.06 | E1: =SUM(E3:E1048576) -> 4329.05 | F1: =SUM(F3:F1048576) -> 1114.5 | G1: =SUM(G3:G1048576) -> 18566.52 | H1: =SUM(H3:H1048576) -> 168.13 | I1: =SUM(I3:I1048576) -> 483 | J1: =SUM(J3:J1048576) -> 4455.28
A2: File Name | B2: Paystub No. | C2: Pay Date | D2: Net Pay | E2: CPP Premium | F2: EI Premium | G2: Federal Tax | H2: Group Insurance Premium | I2: Insurance - L.T.D Premium | J2: RRSP - EE %
A3: =INDEX('Raw Data'!2:2,MATCH(A$2,'Raw Data'!$1:$1,0)) -> 134 2024 23 Jul - 05 Aug TT003576_202416_1.pdf | B3: =LEFT(A3,FIND(" ",A3)-1) -> 134 | C3: =INDEX('Raw Data'!2:2,MATCH(C$2,'Raw Data'!$1:$1,0)) -> 45506 | D3: =INDEX('Raw Data'!2:2,MATCH(D$2,'Raw Data'!$1:$1,0)) -> 2312.5 | E3: {=IF(ISNUMBER(INDEX('Raw Data'!2:2,MATCH("CPP Second Contribution",'Raw Data'!2:2,0)+1)),INDEX('Raw Data'!2:2,MATCH("CPP Second Contribution",'Raw Data'!2:2,0)+1),INDEX('Raw Data'!2:2,MATCH(E$2,'Raw Data'!2:2,0)+1))} -> 193.3 | F3: {=INDEX('Raw Data'!2:2,MATCH(F$2,'Raw Data'!2:2,0)+1)} -> 55.99 | G3: {=INDEX('Raw Data'!2:2,MATCH(G$2,'Raw Data'!2:2,0)+1)} -> 617.2 | H3: {=INDEX('Raw Data'!2:2,MATCH(H$2,'Raw Data'!2:2,0)+1)} -> 6.67 | I3: {=INDEX('Raw Data'!2:2,MATCH(I$2,'Raw Data'!2:2,0)+1)} -> 18.76 | J3: {=INDEX('Raw Data'!2:2,MATCH(J$2,'Raw Data'!2:2,0)+1)} -> 168.65
A4: =INDEX('Raw Data'!3:3,MATCH(A$2,'Raw Data'!$1:$1,0)) -> 135 2024 06 Aug - 19 Aug TT003576_202417_1.pdf | B4: =LEFT(A4,FIND(" ",A4)-1) -> 135 | C4: =INDEX('Raw Data'!3:3,MATCH(C$2,'Raw Data'!$1:$1,0)) -> 45520 | D4: =INDEX('Raw Data'!3:3,MATCH(D$2,'Raw Data'!$1:$1,0)) -> 2312.5 | E4: {=IF(ISNUMBER(INDEX('Raw Data'!3:3,MATCH("CPP Second Contribution",'Raw Data'!3:3,0)+1)),INDEX('Raw Data'!3:3,MATCH("CPP Second Contribution",'Raw Data'!3:3,0)+1),INDEX('Raw Data'!3:3,MATCH(E$2,'Raw Data'!3:3,0)+1))} -> 193.3 | F4: {=INDEX('Raw Data'!3:3,MATCH(F$2,'Raw Data'!3:3,0)+1)} -> 55.99 | G4: {=INDEX('Raw Data'!3:3,MATCH(G$2,'Raw Data'!3:3,0)+1)} -> 617.2 | H4: {=INDEX('Raw Data'!3:3,MATCH(H$2,'Raw Data'!3:3,0)+1)} -> 6.67 | I4: {=INDEX('Raw Data'!3:3,MATCH(I$2,'Raw Data'!3:3,0)+1)} -> 18.76 | J4: {=INDEX('Raw Data'!3:3,MATCH(J$2,'Raw Data'!3:3,0)+1)} -> 168.65
A5: =INDEX('Raw Data'!4:4,MATCH(A$2,'Raw Data'!$1:$1,0)) -> 136 2024 20 Aug - 02 Sep TT003576_202418_1.pdf | B5: =LEFT(A5,FIND(" ",A5)-1) -> 136 | C5: =INDEX('Raw Data'!4:4,MATCH(C$2,'Raw Data'!$1:$1,0)) -> 45534 | D5: =INDEX('Raw Data'!4:4,MATCH(D$2,'Raw Data'!$1:$1,0)) -> 2363.72 | E5: {=IF(ISNUMBER(INDEX('Raw Data'!4:4,MATCH("CPP Second Contribution",'Raw Data'!4:4,0)+1)),INDEX('Raw Data'!4:4,MATCH("CPP Second Contribution",'Raw Data'!4:4,0)+1),INDEX('Raw Data'!4:4,MATCH(E$2,'Raw Data'!4:4,0)+1))} -> 192.69 | F5: {=INDEX('Raw Data'!4:4,MATCH(F$2,'Raw Data'!4:4,0)+1)} -> 33.82 | G5: {=INDEX('Raw Data'!4:4,MATCH(G$2,'Raw Data'!4:4,0)+1)} -> 614.19 | H5: {=INDEX('Raw Data'!4:4,MATCH(H$2,'Raw Data'!4:4,0)+1)} -> 0 | I5: {=INDEX('Raw Data'!4:4,MATCH(I$2,'Raw Data'!4:4,0)+1)} -> 0 | J5: {=INDEX('Raw Data'!4:4,MATCH(J$2,'Raw Data'!4:4,0)+1)} -> 168.65
A6: =INDEX('Raw Data'!5:5,MATCH(A$2,'Raw Data'!$1:$1,0)) -> 137 2024 03 Sep - 16 Sep TT003576_202419_1.pdf | B6: =LEFT(A6,FIND(" ",A6)-1) -> 137 | C6: =INDEX('Raw Data'!5:5,MATCH(C$2,'Raw Data'!$1:$1,0)) -> 45548 | D6: =INDEX('Raw Data'!5:5,MATCH(D$2,'Raw Data'!$1:$1,0)) -> 2397.37 | E6: {=IF(ISNUMBER(INDEX('Raw Data'!5:5,MATCH("CPP Second Contribution",'Raw Data'!5:5,0)+1)),INDEX('Raw Data'!5:5,MATCH("CPP Second Contribution",'Raw Data'!5:5,0)+1),INDEX('Raw Data'!5:5,MATCH(E$2,'Raw Data'!5:5,0)+1))} -> 161.84 | F6: {=INDEX('Raw Data'!5:5,MATCH(F$2,'Raw Data'!5:5,0)+1)} -> 0 | G6: {=INDEX('Raw Data'!5:5,MATCH(G$2,'Raw Data'!5:5,0)+1)} -> 618.61 | H6: {=INDEX('Raw Data'!5:5,MATCH(H$2,'Raw Data'!5:5,0)+1)} -> 6.67 | I6: {=INDEX('Raw Data'!5:5,MATCH(I$2,'Raw Data'!5:5,0)+1)} -> 19.93 | J6: {=INDEX('Raw Data'!5:5,MATCH(J$2,'Raw Data'!5:5,0)+1)} -> 168.65
A7: =INDEX('Raw Data'!6:6,MATCH(A$2,'Raw Data'!$1:$1,0)) -> 138 2024 17 Sep - 30 Sep TT003576_202420_1.pdf | B7: =LEFT(A7,FIND(" ",A7)-1) -> 138 | C7: =INDEX('Raw Data'!6:6,MATCH(C$2,'Raw Data'!$1:$1,0)) -> 45562 | D7: =INDEX('Raw Data'!6:6,MATCH(D$2,'Raw Data'!$1:$1,0)) -> 2466.57 | E7: {=IF(ISNUMBER(INDEX('Raw Data'!6:6,MATCH("CPP Second Contribution",'Raw Data'!6:6,0)+1)),INDEX('Raw Data'!6:6,MATCH("CPP Second Contribution",'Raw Data'!6:6,0)+1),INDEX('Raw Data'!6:6,MATCH(E$2,'Raw Data'!6:6,0)+1))} -> 118.73 | F7: {=INDEX('Raw Data'!6:6,MATCH(F$2,'Raw Data'!6:6,0)+1)} -> 0 | G7: {=INDEX('Raw Data'!6:6,MATCH(G$2,'Raw Data'!6:6,0)+1)} -> 591.47 | H7: {=INDEX('Raw Data'!6:6,MATCH(H$2,'Raw Data'!6:6,0)+1)} -> 7.72 | I7: {=INDEX('Raw Data'!6:6,MATCH(I$2,'Raw Data'!6:6,0)+1)} -> 19.93 | J7: {=INDEX('Raw Data'!6:6,MATCH(J$2,'Raw Data'!6:6,0)+1)} -> 168.65
A8: =INDEX('Raw Data'!7:7,MATCH(A$2,'Raw Data'!$1:$1,0)) -> 139 2024 01 Oct - 14 Oct TT003576_202421_1.pdf | B8: =LEFT(A8,FIND(" ",A8)-1) -> 139 | C8: =INDEX('Raw Data'!7:7,MATCH(C$2,'Raw Data'!$1:$1,0)) -> 45576 | D8: =INDEX('Raw Data'!7:7,MATCH(D$2,'Raw Data'!$1:$1,0)) -> 2502.06 | E8: {=IF(ISNUMBER(INDEX('Raw Data'!7:7,MATCH("CPP Second Contribution",'Raw Data'!7:7,0)+1)),INDEX('Raw Data'!7:7,MATCH("CPP Second Contribution",'Raw Data'!7:7,0)+1),INDEX('Raw Data'!7:7,MATCH(E$2,'Raw Data'!7:7,0)+1))} -> 69.27 | F8: {=INDEX('Raw Data'!7:7,MATCH(F$2,'Raw Data'!7:7,0)+1)} -> 0 | G8: {=INDEX('Raw Data'!7:7,MATCH(G$2,'Raw Data'!7:7,0)+1)} -> 606.14 | H8: {=INDEX('Raw Data'!7:7,MATCH(H$2,'Raw Data'!7:7,0)+1)} -> 7.02 | I8: {=INDEX('Raw Data'!7:7,MATCH(I$2,'Raw Data'!7:7,0)+1)} -> 19.93 | J8: {=INDEX('Raw Data'!7:7,MATCH(J$2,'Raw Data'!7:7,0)+1)} -> 168.65
A9: =INDEX('Raw Data'!8:8,MATCH(A$2,'Raw Data'!$1:$1,0)) -> 140 2024 15 Oct - 28 Oct TT003576_202422_1.pdf | B9: =LEFT(A9,FIND(" ",A9)-1) -> 140 | C9: =INDEX('Raw Data'!8:8,MATCH(C$2,'Raw Data'!$1:$1,0)) -> 45590 | D9: =INDEX('Raw Data'!8:8,MATCH(D$2,'Raw Data'!$1:$1,0)) -> 2550.8 | E9: {=IF(ISNUMBER(INDEX('Raw Data'!8:8,MATCH("CPP Second Contribution",'Raw Data'!8:8,0)+1)),INDEX('Raw Data'!8:8,MATCH("CPP Second Contribution",'Raw Data'!8:8,0)+1),INDEX('Raw Data'!8:8,MATCH(E$2,'Raw Data'!8:8,0)+1))} -> 0 | F9: {=INDEX('Raw Data'!8:8,MATCH(F$2,'Raw Data'!8:8,0)+1)} -> 0 | G9: {=INDEX('Raw Data'!8:8,MATCH(G$2,'Raw Data'!8:8,0)+1)} -> 626.67 | H9: {=INDEX('Raw Data'!8:8,MATCH(H$2,'Raw Data'!8:8,0)+1)} -> 7.02 | I9: {=INDEX('Raw Data'!8:8,MATCH(I$2,'Raw Data'!8:8,0)+1)} -> 19.93 | J9: {=INDEX('Raw Data'!8:8,MATCH(J$2,'Raw Data'!8:8,0)+1)} -> 168.65
A10: =INDEX('Raw Data'!9:9,MATCH(A$2,'Raw Data'!$1:$1,0)) -> 141 2024 29 Oct - 11 Nov TT003576_202423_1.pdf | B10: =LEFT(A10,FIND(" ",A10)-1) -> 141 | C10: =INDEX('Raw Data'!9:9,MATCH(C$2,'Raw Data'!$1:$1,0)) -> 45604 | D10: =INDEX('Raw Data'!9:9,MATCH(D$2,'Raw Data'!$1:$1,0)) -> 2550.8 | E10: {=IF(ISNUMBER(INDEX('Raw Data'!9:9,MATCH("CPP Second Contribution",'Raw Data'!9:9,0)+1)),INDEX('Raw Data'!9:9,MATCH("CPP Second Contribution",'Raw Data'!9:9,0)+1),INDEX('Raw Data'!9:9,MATCH(E$2,'Raw Data'!9:9,0)+1))} -> 0 | F10: {=INDEX('Raw Data'!9:9,MATCH(F$2,'Raw Data'!9:9,0)+1)} -> 0 | G10: {=INDEX('Raw Data'!9:9,MATCH(G$2,'Raw Data'!9:9,0)+1)} -> 626.67 | H10: {=INDEX('Raw Data'!9:9,MATCH(H$2,'Raw Data'!9:9,0)+1)} -> 7.02 | I10: {=INDEX('Raw Data'!9:9,MATCH(I$2,'Raw Data'!9:9,0)+1)} -> 19.93 | J10: {=INDEX('Raw Data'!9:9,MATCH(J$2,'Raw Data'!9:9,0)+1)} -> 168.65
A11: =INDEX('Raw Data'!10:10,MATCH(A$2,'Raw Data'!$1:$1,0)) -> 142 2024 12 Nov - 25 Nov TT003576_202424_1.pdf | B11: =LEFT(A11,FIND(" ",A11)-1) -> 142 | C11: =INDEX('Raw Data'!10:10,MATCH(C$2,'Raw Data'!$1:$1,0)) -> 45618 | D11: =INDEX('Raw Data'!10:10,MATCH(D$2,'Raw Data'!$1:$1,0)) -> 2831.48 | E11: {=IF(ISNUMBER(INDEX('Raw Data'!10:10,MATCH("CPP Second Contribution",'Raw Data'!10:10,0)+1)),INDEX('Raw Data'!10:10,MATCH("CPP Second Contribution",'Raw Data'!10:10,0)+1),INDEX('Raw Data'!10:10,MATCH(E$2,'Raw Data'!10:10,0)+1))} -> 0 | F11: {=INDEX('Raw Data'!10:10,MATCH(F$2,'Raw Data'!10:10,0)+1)} -> 0 | G11: {=INDEX('Raw Data'!10:10,MATCH(G$2,'Raw Data'!10:10,0)+1)} -> 745.99 | H11: {=INDEX('Raw Data'!10:10,MATCH(H$2,'Raw Data'!10:10,0)+1)} -> 7.02 | I11: {=INDEX('Raw Data'!10:10,MATCH(I$2,'Raw Data'!10:10,0)+1)} -> 19.93 | J11: {=INDEX('Raw Data'!10:10,MATCH(J$2,'Raw Data'!10:10,0)+1)} -> 168.65
A12: =INDEX('Raw Data'!11:11,MATCH(A$2,'Raw Data'!$1:$1,0)) -> 143 2024 26 Nov - 09 Dec TT003576_202425_1.pdf | B12: =LEFT(A12,FIND(" ",A12)-1) -> 143 | C12: =INDEX('Raw Data'!11:11,MATCH(C$2,'Raw Data'!$1:$1,0)) -> 45632 | D12: =INDEX('Raw Data'!11:11,MATCH(D$2,'Raw Data'!$1:$1,0)) -> 2550.8 | E12: {=IF(ISNUMBER(INDEX('Raw Data'!11:11,MATCH("CPP Second Contribution",'Raw Data'!11:11,0)+1)),INDEX('Raw Data'!11:11,MATCH("CPP Second Contribution",'Raw Data'!11:11,0)+1),INDEX('Raw Data'!11:11,MATCH(E$2,'Raw Data'!11:11,0)+1))} -> 0 | F12: {=INDEX('Raw Data'!11:11,MATCH(F$2,'Raw Data'!11:11,0)+1)} -> 0 | G12: {=INDEX('Raw Data'!11:11,MATCH(G$2,'Raw Data'!11:11,0)+1)} -> 626.67 | H12: {=INDEX('Raw Data'!11:11,MATCH(H$2,'Raw Data'!11:11,0)+1)} -> 7.02 | I12: {=INDEX('Raw Data'!11:11,MATCH(I$2,'Raw Data'!11:11,0)+1)} -> 19.93 | J12: {=INDEX('Raw Data'!11:11,MATCH(J$2,'Raw Data'!11:11,0)+1)} -> 168.65
A13: =INDEX('Raw Data'!12:12,MATCH(A$2,'Raw Data'!$1:$1,0)) -> 144 2024 10 Dec - 23 Dec TT003576_202426_1.pdf | B13: =LEFT(A13,FIND(" ",A13)-1) -> 144 | C13: =INDEX('Raw Data'!12:12,MATCH(C$2,'Raw Data'!$1:$1,0)) -> 45646 | D13: =INDEX('Raw Data'!12:12,MATCH(D$2,'Raw Data'!$1:$1,0)) -> 2550.8 | E13: {=IF(ISNUMBER(INDEX('Raw Data'!12:12,MATCH("CPP Second Contribution",'Raw Data'!12:12,0)+1)),INDEX('Raw Data'!12:12,MATCH("CPP Second Contribution",'Raw Data'!12:12,0)+1),INDEX('Raw Data'!12:12,MATCH(E$2,'Raw Data'!12:12,0)+1))} -> 0 | F13: {=INDEX('Raw Data'!12:12,MATCH(F$2,'Raw Data'!12:12,0)+1)} -> 0 | G13: {=INDEX('Raw Data'!12:12,MATCH(G$2,'Raw Data'!12:12,0)+1)} -> 626.67 | H13: {=INDEX('Raw Data'!12:12,MATCH(H$2,'Raw Data'!12:12,0)+1)} -> 7.02 | I13: {=INDEX('Raw Data'!12:12,MATCH(I$2,'Raw Data'!12:12,0)+1)} -> 19.93 | J13: {=INDEX('Raw Data'!12:12,MATCH(J$2,'Raw Data'!12:12,0)+1)} -> 168.65
A14: =INDEX('Raw Data'!13:13,MATCH(A$2,'Raw Data'!$1:$1,0)) -> 145 2024 24 Dec - 2025 06 Jan TT003576_202501_1.pdf | B14: =LEFT(A14,FIND(" ",A14)-1) -> 145 | C14: =INDEX('Raw Data'!13:13,MATCH(C$2,'Raw Data'!$1:$1,0)) -> 45660 | D14: =INDEX('Raw Data'!13:13,MATCH(D$2,'Raw Data'!$1:$1,0)) -> 2311.17 | E14: {=IF(ISNUMBER(INDEX('Raw Data'!13:13,MATCH("CPP Second Contribution",'Raw Data'!13:13,0)+1)),INDEX('Raw Data'!13:13,MATCH("CPP Second Contribution",'Raw Data'!13:13,0)+1),INDEX('Raw Data'!13:13,MATCH(E$2,'Raw Data'!13:13,0)+1))} -> 193.27 | F14: {=INDEX('Raw Data'!13:13,MATCH(F$2,'Raw Data'!13:13,0)+1)} -> 55.99 | G14: {=INDEX('Raw Data'!13:13,MATCH(G$2,'Raw Data'!13:13,0)+1)} -> 617.04 | H14: {=INDEX('Raw Data'!13:13,MATCH(H$2,'Raw Data'!13:13,0)+1)} -> 7.02 | I14: {=INDEX('Raw Data'!13:13,MATCH(I$2,'Raw Data'!13:13,0)+1)} -> 19.93 | J14: {=INDEX('Raw Data'!13:13,MATCH(J$2,'Raw Data'!13:13,0)+1)} -> 168.65
A15: =INDEX('Raw Data'!14:14,MATCH(A$2,'Raw Data'!$1:$1,0)) -> 146 2025 07 Jan - 20 Jan TT003576_202502_1.pdf | B15: =LEFT(A15,FIND(" ",A15)-1) -> 146 | C15: =INDEX('Raw Data'!14:14,MATCH(C$2,'Raw Data'!$1:$1,0)) -> 45674 | D15: =INDEX('Raw Data'!14:14,MATCH(D$2,'Raw Data'!$1:$1,0)) -> 2321.93 | E15: {=IF(ISNUMBER(INDEX('Raw Data'!14:14,MATCH("CPP Second Contribution",'Raw Data'!14:14,0)+1)),INDEX('Raw Data'!14:14,MATCH("CPP Second Contribution",'Raw Data'!14:14,0)+1),INDEX('Raw Data'!14:14,MATCH(E$2,'Raw Data'!14:14,0)+1))} -> 193.27 | F15: {=INDEX('Raw Data'!14:14,MATCH(F$2,'Raw Data'!14:14,0)+1)} -> 55.32 | G15: {=INDEX('Raw Data'!14:14,MATCH(G$2,'Raw Data'!14:14,0)+1)} -> 606.95 | H15: {=INDEX('Raw Data'!14:14,MATCH(H$2,'Raw Data'!14:14,0)+1)} -> 7.02 | I15: {=INDEX('Raw Data'!14:14,MATCH(I$2,'Raw Data'!14:14,0)+1)} -> 19.93 | J15: {=INDEX('Raw Data'!14:14,MATCH(J$2,'Raw Data'!14:14,0)+1)} -> 168.65
A16: =INDEX('Raw Data'!15:15,MATCH(A$2,'Raw Data'!$1:$1,0)) -> 147 21 Jan 2025 - 03 Feb 2025 TT003576_202503_1.pdf | B16: =LEFT(A16,FIND(" ",A16)-1) -> 147 | C16: =INDEX('Raw Data'!15:15,MATCH(C$2,'Raw Data'!$1:$1,0)) -> 45688 | D16: =INDEX('Raw Data'!15:15,MATCH(D$2,'Raw Data'!$1:$1,0)) -> 2352.31 | E16: {=IF(ISNUMBER(INDEX('Raw Data'!15:15,MATCH("CPP Second Contribution",'Raw Data'!15:15,0)+1)),INDEX('Raw Data'!15:15,MATCH("CPP Second Contribution",'Raw Data'!15:15,0)+1),INDEX('Raw Data'!15:15,MATCH(E$2,'Raw Data'!15:15,0)+1))} -> 192.69 | F16: {=INDEX('Raw Data'!15:15,MATCH(F$2,'Raw Data'!15:15,0)+1)} -> 55.32 | G16: {=INDEX('Raw Data'!15:15,MATCH(G$2,'Raw Data'!15:15,0)+1)} -> 604.1 | H16: {=INDEX('Raw Data'!15:15,MATCH(H$2,'Raw Data'!15:15,0)+1)} -> 0 | I16: {=INDEX('Raw Data'!15:15,MATCH(I$2,'Raw Data'!15:15,0)+1)} -> 0 | J16: {=INDEX('Raw Data'!15:15,MATCH(J$2,'Raw Data'!15:15,0)+1)} -> 168.65
A17: =INDEX('Raw Data'!16:16,MATCH(A$2,'Raw Data'!$1:$1,0)) -> 148 04 Feb 2025 - 17 Feb 2025 TT003576_202504_1.pdf | B17: =LEFT(A17,FIND(" ",A17)-1) -> 148 | C17: =INDEX('Raw Data'!16:16,MATCH(C$2,'Raw Data'!$1:$1,0)) -> 45702 | D17: =INDEX('Raw Data'!16:16,MATCH(D$2,'Raw Data'!$1:$1,0)) -> 2321.93 | E17: {=IF(ISNUMBER(INDEX('Raw Data'!16:16,MATCH("CPP Second Contribution",'Raw Data'!16:16,0)+1)),INDEX('Raw Data'!16:16,MATCH("CPP Second Contribution",'Raw Data'!16:16,0)+1),INDEX('Raw Data'!16:16,MATCH(E$2,'Raw Data'!16:16,0)+1))} -> 193.27 | F17: {=INDEX('Raw Data'!16:16,MATCH(F$2,'Raw Data'!16:16,0)+1)} -> 55.32 | G17: {=INDEX('Raw Data'!16:16,MATCH(G$2,'Raw Data'!16:16,0)+1)} -> 606.95 | H17: {=INDEX('Raw Data'!16:16,MATCH(H$2,'Raw Data'!16:16,0)+1)} -> 7.02 | I17: {=INDEX('Raw Data'!16:16,MATCH(I$2,'Raw Data'!16:16,0)+1)} -> 19.93 | J17: {=INDEX('Raw Data'!16:16,MATCH(J$2,'Raw Data'!16:16,0)+1)} -> 168.65
A18: =INDEX('Raw Data'!17:17,MATCH(A$2,'Raw Data'!$1:$1,0)) -> 149 18 Feb 2025 - 03 Mar 2025 TT003576_202505_1.pdf | B18: =LEFT(A18,FIND(" ",A18)-1) -> 149 | C18: =INDEX('Raw Data'!17:17,MATCH(C$2,'Raw Data'!$1:$1,0)) -> 45716 | D18: =INDEX('Raw Data'!17:17,MATCH(D$2,'Raw Data'!$1:$1,0)) -> 2321.93 | E18: {=IF(ISNUMBER(INDEX('Raw Data'!17:17,MATCH("CPP Second Contribution",'Raw Data'!17:17,0)+1)),INDEX('Raw Data'!17:17,MATCH("CPP Second Contribution",'Raw Data'!17:17,0)+1),INDEX('Raw Data'!17:17,MATCH(E$2,'Raw Data'!17:17,0)+1))} -> 193.27 | F18: {=INDEX('Raw Data'!17:17,MATCH(F$2,'Raw Data'!17:17,0)+1)} -> 55.32 | G18: {=INDEX('Raw Data'!17:17,MATCH(G$2,'Raw Data'!17:17,0)+1)} -> 606.95 | H18: {=INDEX('Raw Data'!17:17,MATCH(H$2,'Raw Data'!17:17,0)+1)} -> 7.02 | I18: {=INDEX('Raw Data'!17:17,MATCH(I$2,'Raw Data'!17:17,0)+1)} -> 19.93 | J18: {=INDEX('Raw Data'!17:17,MATCH(J$2,'Raw Data'!17:17,0)+1)} -> 168.65
A19: =INDEX('Raw Data'!18:18,MATCH(A$2,'Raw Data'!$1:$1,0)) -> 150 04 Mar 2025 - 17 Mar 2025 TT003576_202506_1.pdf | B19: =LEFT(A19,FIND(" ",A19)-1) -> 150 | C19: =INDEX('Raw Data'!18:18,MATCH(C$2,'Raw Data'!$1:$1,0)) -> 45730 | D19: =INDEX('Raw Data'!18:18,MATCH(D$2,'Raw Data'!$1:$1,0)) -> 2321.93 | E19: {=IF(ISNUMBER(INDEX('Raw Data'!18:18,MATCH("CPP Second Contribution",'Raw Data'!18:18,0)+1)),INDEX('Raw Data'!18:18,MATCH("CPP Second Contribution",'Raw Data'!18:18,0)+1),INDEX('Raw Data'!18:18,MATCH(E$2,'Raw Data'!18:18,0)+1))} -> 193.27 | F19: {=INDEX('Raw Data'!18:18,MATCH(F$2,'Raw Data'!18:18,0)+1)} -> 55.32 | G19: {=INDEX('Raw Data'!18:18,MATCH(G$2,'Raw Data'!18:18,0)+1)} -> 606.95 | H19: {=INDEX('Raw Data'!18:18,MATCH(H$2,'Raw Data'!18:18,0)+1)} -> 7.02 | I19: {=INDEX('Raw Data'!18:18,MATCH(I$2,'Raw Data'!18:18,0)+1)} -> 19.93 | J19: {=INDEX('Raw Data'!18:18,MATCH(J$2,'Raw Data'!18:18,0)+1)} -> 168.65
A20: =INDEX('Raw Data'!19:19,MATCH(A$2,'Raw Data'!$1:$1,0)) -> 151 18 Mar 2025 - 31 Mar 2025 TT003576_202507_1.pdf | B20: =LEFT(A20,FIND(" ",A20)-1) -> 151 | C20: =INDEX('Raw Data'!19:19,MATCH(C$2,'Raw Data'!$1:$1,0)) -> 45744 | D20: =INDEX('Raw Data'!19:19,MATCH(D$2,'Raw Data'!$1:$1,0)) -> 2321.93 | E20: {=IF(ISNUMBER(INDEX('Raw Data'!19:19,MATCH("CPP Second Contribution",'Raw Data'!19:19,0)+1)),INDEX('Raw Data'!19:19,MATCH("CPP Second Contribution",'Raw Data'!19:19,0)+1),INDEX('Raw Data'!19:19,MATCH(E$2,'Raw Data'!19:19,0)+1))} -> 193.27 | F20: {=INDEX('Raw Data'!19:19,MATCH(F$2,'Raw Data'!19:19,0)+1)} -> 55.32 | G20: {=INDEX('Raw Data'!19:19,MATCH(G$2,'Raw Data'!19:19,0)+1)} -> 606.95 | H20: {=INDEX('Raw Data'!19:19,MATCH(H$2,'Raw Data'!19:19,0)+1)} -> 7.02 | I20: {=INDEX('Raw Data'!19:19,MATCH(I$2,'Raw Data'!19:19,0)+1)} -> 19.93 | J20: {=INDEX('Raw Data'!19:19,MATCH(J$2,'Raw Data'!19:19,0)+1)} -> 168.65
A21: =INDEX('Raw Data'!20:20,MATCH(A$2,'Raw Data'!$1:$1,0)) -> 152 01 Apr 2025 - 14 Apr 2025 TT003576_202508_1.pdf | B21: =LEFT(A21,FIND(" ",A21)-1) -> 152 | C21: =INDEX('Raw Data'!20:20,MATCH(C$2,'Raw Data'!$1:$1,0)) -> 45758 | D21: =INDEX('Raw Data'!20:20,MATCH(D$2,'Raw Data'!$1:$1,0)) -> 2321.93 | E21: {=IF(ISNUMBER(INDEX('Raw Data'!20:20,MATCH("CPP Second Contribution",'Raw Data'!20:20,0)+1)),INDEX('Raw Data'!20:20,MATCH("CPP Second Contribution",'Raw Data'!20:20,0)+1),INDEX('Raw Data'!20:20,MATCH(E$2,'Raw Data'!20:20,0)+1))} -> 193.27 | F21: {=INDEX('Raw Data'!20:20,MATCH(F$2,'Raw Data'!20:20,0)+1)} -> 55.32 | G21: {=INDEX('Raw Data'!20:20,MATCH(G$2,'Raw Data'!20:20,0)+1)} -> 606.95 | H21: {=INDEX('Raw Data'!20:20,MATCH(H$2,'Raw Data'!20:20,0)+1)} -> 7.02 | I21: {=INDEX('Raw Data'!20:20,MATCH(I$2,'Raw Data'!20:20,0)+1)} -> 19.93 | J21: {=INDEX('Raw Data'!20:20,MATCH(J$2,'Raw Data'!20:20,0)+1)} -> 168.65
A22: =INDEX('Raw Data'!21:21,MATCH(A$2,'Raw Data'!$1:$1,0)) -> 152 01 Apr 2025 - 14 Apr 2025 TT003576_202508_2 bonus.pdf | B22: =LEFT(A22,FIND(" ",A22)-1) -> 152 | C22: =INDEX('Raw Data'!21:21,MATCH(C$2,'Raw Data'!$1:$1,0)) -> 45758 | D22: =INDEX('Raw Data'!21:21,MATCH(D$2,'Raw Data'!$1:$1,0)) -> 4314.85 | E22: {=IF(ISNUMBER(INDEX('Raw Data'!21:21,MATCH("CPP Second Contribution",'Raw Data'!21:21,0)+1)),INDEX('Raw Data'!21:21,MATCH("CPP Second Contribution",'Raw Data'!21:21,0)+1),INDEX('Raw Data'!21:21,MATCH(E$2,'Raw Data'!21:21,0)+1))} -> 417.69 | F22: {=INDEX('Raw Data'!21:21,MATCH(F$2,'Raw Data'!21:21,0)+1)} -> 115.13 | G22: {=INDEX('Raw Data'!21:21,MATCH(G$2,'Raw Data'!21:21,0)+1)} -> 2172.33 | H22: {=INDEX('Raw Data'!21:21,MATCH(H$2,'Raw Data'!21:21,0)+1)} -> 0 | I22: {=INDEX('Raw Data'!21:21,MATCH(I$2,'Raw Data'!21:21,0)+1)} -> 0 | J22: {=INDEX('Raw Data'!21:21,MATCH(J$2,'Raw Data'!21:21,0)+1)} -> 0
A23: =INDEX('Raw Data'!22:22,MATCH(A$2,'Raw Data'!$1:$1,0)) -> 153 15 Apr 2025 - 28 Apr 2025 TT003576_202509_1.pdf | B23: =LEFT(A23,FIND(" ",A23)-1) -> 153 | C23: =INDEX('Raw Data'!22:22,MATCH(C$2,'Raw Data'!$1:$1,0)) -> 45772 | D23: =INDEX('Raw Data'!22:22,MATCH(D$2,'Raw Data'!$1:$1,0)) -> 2321.93 | E23: {=IF(ISNUMBER(INDEX('Raw Data'!22:22,MATCH("CPP Second Contribution",'Raw Data'!22:22,0)+1)),INDEX('Raw Data'!22:22,MATCH("CPP Second Contribution",'Raw Data'!22:22,0)+1),INDEX('Raw Data'!22:22,MATCH(E$2,'Raw Data'!22:22,0)+1))} -> 193.27 | F23: {=INDEX('Raw Data'!22:22,MATCH(F$2,'Raw Data'!22:22,0)+1)} -> 55.32 | G23: {=INDEX('Raw Data'!22:22,MATCH(G$2,'Raw Data'!22:22,0)+1)} -> 606.95 | H23: {=INDEX('Raw Data'!22:22,MATCH(H$2,'Raw Data'!22:22,0)+1)} -> 7.02 | I23: {=INDEX('Raw Data'!22:22,MATCH(I$2,'Raw Data'!22:22,0)+1)} -> 19.93 | J23: {=INDEX('Raw Data'!22:22,MATCH(J$2,'Raw Data'!22:22,0)+1)} -> 168.65
A24: =INDEX('Raw Data'!23:23,MATCH(A$2,'Raw Data'!$1:$1,0)) -> 154 29 Apr 2025 - 12 May 2025 TT003576_202510_1.pdf | B24: =LEFT(A24,FIND(" ",A24)-1) -> 154 | C24: =INDEX('Raw Data'!23:23,MATCH(C$2,'Raw Data'!$1:$1,0)) -> 45786 | D24: =INDEX('Raw Data'!23:23,MATCH(D$2,'Raw Data'!$1:$1,0)) -> 2461.62 | E24: {=IF(ISNUMBER(INDEX('Raw Data'!23:23,MATCH("CPP Second Contribution",'Raw Data'!23:23,0)+1)),INDEX('Raw Data'!23:23,MATCH("CPP Second Contribution",'Raw Data'!23:23,0)+1),INDEX('Raw Data'!23:23,MATCH(E$2,'Raw Data'!23:23,0)+1))} -> 207.23 | F24: {=INDEX('Raw Data'!23:23,MATCH(F$2,'Raw Data'!23:23,0)+1)} -> 59.17 | G24: {=INDEX('Raw Data'!23:23,MATCH(G$2,'Raw Data'!23:23,0)+1)} -> 672.34 | H24: {=INDEX('Raw Data'!23:23,MATCH(H$2,'Raw Data'!23:23,0)+1)} -> 7.02 | I24: {=INDEX('Raw Data'!23:23,MATCH(I$2,'Raw Data'!23:23,0)+1)} -> 19.93 | J24: {=INDEX('Raw Data'!23:23,MATCH(J$2,'Raw Data'!23:23,0)+1)} -> 180.38
A25: =INDEX('Raw Data'!24:24,MATCH(A$2,'Raw Data'!$1:$1,0)) -> 155 13 May 2025 - 26 May 2025 TT003576_202511_1.pdf | B25: =LEFT(A25,FIND(" ",A25)-1) -> 155 | C25: =INDEX('Raw Data'!24:24,MATCH(C$2,'Raw Data'!$1:$1,0)) -> 45800 | D25: =INDEX('Raw Data'!24:24,MATCH(D$2,'Raw Data'!$1:$1,0)) -> 2461.62 | E25: {=IF(ISNUMBER(INDEX('Raw Data'!24:24,MATCH("CPP Second Contribution",'Raw Data'!24:24,0)+1)),INDEX('Raw Data'!24:24,MATCH("CPP Second Contribution",'Raw Data'!24:24,0)+1),INDEX('Raw Data'!24:24,MATCH(E$2,'Raw Data'!24:24,0)+1))} -> 207.23 | F25: {=INDEX('Raw Data'!24:24,MATCH(F$2,'Raw Data'!24:24,0)+1)} -> 59.17 | G25: {=INDEX('Raw Data'!24:24,MATCH(G$2,'Raw Data'!24:24,0)+1)} -> 672.34 | H25: {=INDEX('Raw Data'!24:24,MATCH(H$2,'Raw Data'!24:24,0)+1)} -> 7.02 | I25: {=INDEX('Raw Data'!24:24,MATCH(I$2,'Raw Data'!24:24,0)+1)} -> 19.93 | J25: {=INDEX('Raw Data'!24:24,MATCH(J$2,'Raw Data'!24:24,0)+1)} -> 180.38
A26: =INDEX('Raw Data'!25:25,MATCH(A$2,'Raw Data'!$1:$1,0)) -> 156 27 May 2025 - 09 Jun 2025 TT003576_202512_1.pdf | B26: =LEFT(A26,FIND(" ",A26)-1) -> 156 | C26: =INDEX('Raw Data'!25:25,MATCH(C$2,'Raw Data'!$1:$1,0)) -> 45814 | D26: =INDEX('Raw Data'!25:25,MATCH(D$2,'Raw Data'!$1:$1,0)) -> 2459.28 | E26: {=IF(ISNUMBER(INDEX('Raw Data'!25:25,MATCH("CPP Second Contribution",'Raw Data'!25:25,0)+1)),INDEX('Raw Data'!25:25,MATCH("CPP Second Contribution",'Raw Data'!25:25,0)+1),INDEX('Raw Data'!25:25,MATCH(E$2,'Raw Data'!25:25,0)+1))} -> 207.23 | F26: {=INDEX('Raw Data'!25:25,MATCH(F$2,'Raw Data'!25:25,0)+1)} -> 59.17 | G26: {=INDEX('Raw Data'!25:25,MATCH(G$2,'Raw Data'!25:25,0)+1)} -> 672.34 | H26: {=INDEX('Raw Data'!25:25,MATCH(H$2,'Raw Data'!25:25,0)+1)} -> 7.02 | I26: {=INDEX('Raw Data'!25:25,MATCH(I$2,'Raw Data'!25:25,0)+1)} -> 22.27 | J26: {=INDEX('Raw Data'!25:25,MATCH(J$2,'Raw Data'!25:25,0)+1)} -> 180.38
A27: =INDEX('Raw Data'!26:26,MATCH(A$2,'Raw Data'!$1:$1,0)) -> 157 10 Jun 2025 - 23 Jun 2025 TT003576_202513_1.pdf | B27: =LEFT(A27,FIND(" ",A27)-1) -> 157 | C27: =INDEX('Raw Data'!26:26,MATCH(C$2,'Raw Data'!$1:$1,0)) -> 45828 | D27: =INDEX('Raw Data'!26:26,MATCH(D$2,'Raw Data'!$1:$1,0)) -> 2459.28 | E27: {=IF(ISNUMBER(INDEX('Raw Data'!26:26,MATCH("CPP Second Contribution",'Raw Data'!26:26,0)+1)),INDEX('Raw Data'!26:26,MATCH("CPP Second Contribution",'Raw Data'!26:26,0)+1),INDEX('Raw Data'!26:26,MATCH(E$2,'Raw Data'!26:26,0)+1))} -> 207.23 | F27: {=INDEX('Raw Data'!26:26,MATCH(F$2,'Raw Data'!26:26,0)+1)} -> 59.17 | G27: {=INDEX('Raw Data'!26:26,MATCH(G$2,'Raw Data'!26:26,0)+1)} -> 672.34 | H27: {=INDEX('Raw Data'!26:26,MATCH(H$2,'Raw Data'!26:26,0)+1)} -> 7.02 | I27: {=INDEX('Raw Data'!26:26,MATCH(I$2,'Raw Data'!26:26,0)+1)} -> 22.27 | J27: {=INDEX('Raw Data'!26:26,MATCH(J$2,'Raw Data'!26:26,0)+1)} -> 180.38
A28: =INDEX('Raw Data'!27:27,MATCH(A$2,'Raw Data'!$1:$1,0)) -> 158 24 Jun 2025 - 07 Jul 2025 TT003576_202514_1.pdf | B28: =LEFT(A28,FIND(" ",A28)-1) -> 158 | C28: =INDEX('Raw Data'!27:27,MATCH(C$2,'Raw Data'!$1:$1,0)) -> 45842 | D28: =INDEX('Raw Data'!27:27,MATCH(D$2,'Raw Data'!$1:$1,0)) -> 2474.01 | E28: {=IF(ISNUMBER(INDEX('Raw Data'!27:27,MATCH("CPP Second Contribution",'Raw Data'!27:27,0)+1)),INDEX('Raw Data'!27:27,MATCH("CPP Second Contribution",'Raw Data'!27:27,0)+1),INDEX('Raw Data'!27:27,MATCH(E$2,'Raw Data'!27:27,0)+1))} -> 207.23 | F28: {=INDEX('Raw Data'!27:27,MATCH(F$2,'Raw Data'!27:27,0)+1)} -> 59.17 | G28: {=INDEX('Raw Data'!27:27,MATCH(G$2,'Raw Data'!27:27,0)+1)} -> 658.78 | H28: {=INDEX('Raw Data'!27:27,MATCH(H$2,'Raw Data'!27:27,0)+1)} -> 7.02 | I28: {=INDEX('Raw Data'!27:27,MATCH(I$2,'Raw Data'!27:27,0)+1)} -> 21.1 | J28: {=INDEX('Raw Data'!27:27,MATCH(J$2,'Raw Data'!27:27,0)+1)} -> 180.38
